Fri Sep  6 05:00:01 UTC 2019
Refreshing report test
Error executing Jupyter command 'nbconvert--to': [Errno 2] No such file or directory
Fri Sep  6 05:05:01 UTC 2019
Refreshing report test
[NbConvertApp] Converting notebook Untitled.ipynb to notebook
[NbConvertApp] Executing notebook with kernel: python3
[NbConvertApp] Writing 1049 bytes to Untitled.ipynb
Fri Sep  6 21:05:01 UTC 2019
Refreshing report test
Error executing Jupyter command 'nbconvert--to': [Errno 2] No such file or directory
Refreshing report testttttt
[NbConvertApp] Converting notebook Untitled.ipynb to notebook
[NbConvertApp] Executing notebook with kernel: python3
[NbConvertApp] Writing 1050 bytes to Untitled.ipynb
Sat Sep  7 18:30:01 UTC 2019
Refreshing report01a
[NbConvertApp] Converting notebook 01a-editor-month-table.ipynb to notebook
[NbConvertApp] Executing notebook with kernel: python3
[NbConvertApp] ERROR | Error while converting '01a-editor-month-table.ipynb'
Traceback (most recent call last):
  File "/home/conniecc1/venv/lib/python3.5/site-packages/nbconvert/nbconvertapp.py", line 393, in export_single_notebook
    output, resources = self.exporter.from_filename(notebook_filename, resources=resources)
  File "/home/conniecc1/venv/lib/python3.5/site-packages/nbconvert/exporters/exporter.py", line 174, in from_filename
    return self.from_file(f, resources=resources, **kw)
  File "/home/conniecc1/venv/lib/python3.5/site-packages/nbconvert/exporters/exporter.py", line 192, in from_file
    return self.from_notebook_node(nbformat.read(file_stream, as_version=4), resources=resources, **kw)
  File "/home/conniecc1/venv/lib/python3.5/site-packages/nbconvert/exporters/notebook.py", line 31, in from_notebook_node
    nb_copy, resources = super(NotebookExporter, self).from_notebook_node(nb, resources, **kw)
  File "/home/conniecc1/venv/lib/python3.5/site-packages/nbconvert/exporters/exporter.py", line 134, in from_notebook_node
    nb_copy, resources = self._preprocess(nb_copy, resources)
  File "/home/conniecc1/venv/lib/python3.5/site-packages/nbconvert/exporters/exporter.py", line 311, in _preprocess
    nbc, resc = preprocessor(nbc, resc)
  File "/home/conniecc1/venv/lib/python3.5/site-packages/nbconvert/preprocessors/base.py", line 47, in __call__
    return self.preprocess(nb, resources)
  File "/home/conniecc1/venv/lib/python3.5/site-packages/nbconvert/preprocessors/execute.py", line 262, in preprocess
    nb, resources = super(ExecutePreprocessor, self).preprocess(nb, resources)
  File "/home/conniecc1/venv/lib/python3.5/site-packages/nbconvert/preprocessors/base.py", line 69, in preprocess
    nb.cells[index], resources = self.preprocess_cell(cell, resources, index)
  File "/home/conniecc1/venv/lib/python3.5/site-packages/nbconvert/preprocessors/execute.py", line 286, in preprocess_cell
    raise CellExecutionError.from_cell_and_msg(cell, out)
nbconvert.preprocessors.execute.CellExecutionError: An error occurred while executing the following cell:
------------------
# UPDATE FOR NEW MONTH!
# Metric month. The mediawiki_history snapshot for this month must be available.
METRICS_MONTH_TEXT = "2019-07"
MEDIAWIKI_HISTORY_SNAPSHOT = "2019-07"

metrics_month = pd.Period(METRICS_MONTH_TEXT)
insert_start = str(metrics_month)
insert_end = str(metrics_month + 1)
graph_start = str(metrics_month - 48)
------------------

[0;31m---------------------------------------------------------------------------[0m
[0;31mNameError[0m                                 Traceback (most recent call last)
[0;32m<ipython-input-1-8e79639b33bd>[0m in [0;36m<module>[0;34m()[0m
[1;32m      4[0m [0mMEDIAWIKI_HISTORY_SNAPSHOT[0m [0;34m=[0m [0;34m"2019-07"[0m[0;34m[0m[0m
[1;32m      5[0m [0;34m[0m[0m
[0;32m----> 6[0;31m [0mmetrics_month[0m [0;34m=[0m [0mpd[0m[0;34m.[0m[0mPeriod[0m[0;34m([0m[0mMETRICS_MONTH_TEXT[0m[0;34m)[0m[0;34m[0m[0m
[0m[1;32m      7[0m [0minsert_start[0m [0;34m=[0m [0mstr[0m[0;34m([0m[0mmetrics_month[0m[0;34m)[0m[0;34m[0m[0m
[1;32m      8[0m [0minsert_end[0m [0;34m=[0m [0mstr[0m[0;34m([0m[0mmetrics_month[0m [0;34m+[0m [0;36m1[0m[0;34m)[0m[0;34m[0m[0m

[0;31mNameError[0m: name 'pd' is not defined
NameError: name 'pd' is not defined

Sun Sep  8 07:28:01 UTC 2019
Refreshing report01a
[NbConvertApp] Converting notebook 01a-editor-month-table.ipynb to notebook
[NbConvertApp] Executing notebook with kernel: python3
[NbConvertApp] ERROR | Error while converting '01a-editor-month-table.ipynb'
Traceback (most recent call last):
  File "/home/conniecc1/venv/lib/python3.5/site-packages/nbconvert/nbconvertapp.py", line 393, in export_single_notebook
    output, resources = self.exporter.from_filename(notebook_filename, resources=resources)
  File "/home/conniecc1/venv/lib/python3.5/site-packages/nbconvert/exporters/exporter.py", line 174, in from_filename
    return self.from_file(f, resources=resources, **kw)
  File "/home/conniecc1/venv/lib/python3.5/site-packages/nbconvert/exporters/exporter.py", line 192, in from_file
    return self.from_notebook_node(nbformat.read(file_stream, as_version=4), resources=resources, **kw)
  File "/home/conniecc1/venv/lib/python3.5/site-packages/nbconvert/exporters/notebook.py", line 31, in from_notebook_node
    nb_copy, resources = super(NotebookExporter, self).from_notebook_node(nb, resources, **kw)
  File "/home/conniecc1/venv/lib/python3.5/site-packages/nbconvert/exporters/exporter.py", line 134, in from_notebook_node
    nb_copy, resources = self._preprocess(nb_copy, resources)
  File "/home/conniecc1/venv/lib/python3.5/site-packages/nbconvert/exporters/exporter.py", line 311, in _preprocess
    nbc, resc = preprocessor(nbc, resc)
  File "/home/conniecc1/venv/lib/python3.5/site-packages/nbconvert/preprocessors/base.py", line 47, in __call__
    return self.preprocess(nb, resources)
  File "/home/conniecc1/venv/lib/python3.5/site-packages/nbconvert/preprocessors/execute.py", line 262, in preprocess
    nb, resources = super(ExecutePreprocessor, self).preprocess(nb, resources)
  File "/home/conniecc1/venv/lib/python3.5/site-packages/nbconvert/preprocessors/base.py", line 69, in preprocess
    nb.cells[index], resources = self.preprocess_cell(cell, resources, index)
  File "/home/conniecc1/venv/lib/python3.5/site-packages/nbconvert/preprocessors/execute.py", line 286, in preprocess_cell
    raise CellExecutionError.from_cell_and_msg(cell, out)
nbconvert.preprocessors.execute.CellExecutionError: An error occurred while executing the following cell:
------------------
create_cmd = Path("queries/create_editor_month.sql").read_text()
update_cmd = Path("queries/update_editor_month.sql").read_text().format(
    start=insert_start,
    end=insert_end,
    mwh_snapshot=MEDIAWIKI_HISTORY_SNAPSHOT
)

hive.run(create_cmd)
hive.run(update_cmd)
------------------

[0;31m---------------------------------------------------------------------------[0m
[0;31mHiveServer2Error[0m                          Traceback (most recent call last)
[0;32m<ipython-input-4-c71bd07994ae>[0m in [0;36m<module>[0;34m()[0m
[1;32m      7[0m [0;34m[0m[0m
[1;32m      8[0m [0mhive[0m[0;34m.[0m[0mrun[0m[0;34m([0m[0mcreate_cmd[0m[0;34m)[0m[0;34m[0m[0m
[0;32m----> 9[0;31m [0mhive[0m[0;34m.[0m[0mrun[0m[0;34m([0m[0mupdate_cmd[0m[0;34m)[0m[0;34m[0m[0m
[0m
[0;32m~/venv/lib/python3.5/site-packages/wmfdata/hive.py[0m in [0;36mrun[0;34m(cmds, fmt)[0m
[1;32m     27[0m [0;34m[0m[0m
[1;32m     28[0m         [0;32mfor[0m [0mcmd[0m [0;32min[0m [0mcmds[0m[0;34m:[0m[0;34m[0m[0m
[0;32m---> 29[0;31m             [0mhive_cursor[0m[0;34m.[0m[0mexecute[0m[0;34m([0m[0mcmd[0m[0;34m)[0m[0;34m[0m[0m
[0m[1;32m     30[0m             [0;32mif[0m [0mfmt[0m [0;34m==[0m [0;34m"pandas"[0m[0;34m:[0m[0;34m[0m[0m
[1;32m     31[0m                 [0;32mtry[0m[0;34m:[0m[0;34m[0m[0m

[0;32m~/venv/lib/python3.5/site-packages/impala/hiveserver2.py[0m in [0;36mexecute[0;34m(self, operation, parameters, configuration)[0m
[1;32m    300[0m         [0;31m# PEP 249[0m[0;34m[0m[0;34m[0m[0m
[1;32m    301[0m         self.execute_async(operation, parameters=parameters,
[0;32m--> 302[0;31m                            configuration=configuration)
[0m[1;32m    303[0m         [0mlog[0m[0;34m.[0m[0mdebug[0m[0;34m([0m[0;34m'Waiting for query to finish'[0m[0;34m)[0m[0;34m[0m[0m
[1;32m    304[0m         [0mself[0m[0;34m.[0m[0m_wait_to_finish[0m[0;34m([0m[0;34m)[0m  [0;31m# make execute synchronous[0m[0;34m[0m[0m

[0;32m~/venv/lib/python3.5/site-packages/impala/hiveserver2.py[0m in [0;36mexecute_async[0;34m(self, operation, parameters, configuration)[0m
[1;32m    341[0m             [0mself[0m[0;34m.[0m[0m_last_operation[0m [0;34m=[0m [0mop[0m[0;34m[0m[0m
[1;32m    342[0m [0;34m[0m[0m
[0;32m--> 343[0;31m         [0mself[0m[0;34m.[0m[0m_execute_async[0m[0;34m([0m[0mop[0m[0;34m)[0m[0;34m[0m[0m
[0m[1;32m    344[0m [0;34m[0m[0m
[1;32m    345[0m     [0;32mdef[0m [0m_debug_log_state[0m[0;34m([0m[0mself[0m[0;34m)[0m[0;34m:[0m[0;34m[0m[0m

[0;32m~/venv/lib/python3.5/site-packages/impala/hiveserver2.py[0m in [0;36m_execute_async[0;34m(self, operation_fn)[0m
[1;32m    360[0m         [0mself[0m[0;34m.[0m[0m_reset_state[0m[0;34m([0m[0;34m)[0m[0;34m[0m[0m
[1;32m    361[0m         [0mself[0m[0;34m.[0m[0m_debug_log_state[0m[0;34m([0m[0;34m)[0m[0;34m[0m[0m
[0;32m--> 362[0;31m         [0moperation_fn[0m[0;34m([0m[0;34m)[0m[0;34m[0m[0m
[0m[1;32m    363[0m         [0mself[0m[0;34m.[0m[0m_last_operation_active[0m [0;34m=[0m [0;32mTrue[0m[0;34m[0m[0m
[1;32m    364[0m         [0mself[0m[0;34m.[0m[0m_debug_log_state[0m[0;34m([0m[0;34m)[0m[0;34m[0m[0m

[0;32m~/venv/lib/python3.5/site-packages/impala/hiveserver2.py[0m in [0;36mop[0;34m()[0m
[1;32m    338[0m             op = self.session.execute(self._last_operation_string,
[1;32m    339[0m                                       [0mconfiguration[0m[0;34m,[0m[0;34m[0m[0m
[0;32m--> 340[0;31m                                       async=True)
[0m[1;32m    341[0m             [0mself[0m[0;34m.[0m[0m_last_operation[0m [0;34m=[0m [0mop[0m[0;34m[0m[0m
[1;32m    342[0m [0;34m[0m[0m

[0;32m~/venv/lib/python3.5/site-packages/impala/hiveserver2.py[0m in [0;36mexecute[0;34m(self, statement, configuration, async)[0m
[1;32m   1025[0m                                    [0mconfOverlay[0m[0;34m=[0m[0mconfiguration[0m[0;34m,[0m[0;34m[0m[0m
[1;32m   1026[0m                                    runAsync=async)
[0;32m-> 1027[0;31m         [0;32mreturn[0m [0mself[0m[0;34m.[0m[0m_operation[0m[0;34m([0m[0;34m'ExecuteStatement'[0m[0;34m,[0m [0mreq[0m[0;34m)[0m[0;34m[0m[0m
[0m[1;32m   1028[0m [0;34m[0m[0m
[1;32m   1029[0m     [0;32mdef[0m [0mget_databases[0m[0;34m([0m[0mself[0m[0;34m,[0m [0mschema[0m[0;34m=[0m[0;34m'.*'[0m[0;34m)[0m[0;34m:[0m[0;34m[0m[0m

[0;32m~/venv/lib/python3.5/site-packages/impala/hiveserver2.py[0m in [0;36m_operation[0;34m(self, kind, request)[0m
[1;32m    955[0m [0;34m[0m[0m
[1;32m    956[0m     [0;32mdef[0m [0m_operation[0m[0;34m([0m[0mself[0m[0;34m,[0m [0mkind[0m[0;34m,[0m [0mrequest[0m[0;34m)[0m[0;34m:[0m[0;34m[0m[0m
[0;32m--> 957[0;31m         [0mresp[0m [0;34m=[0m [0mself[0m[0;34m.[0m[0m_rpc[0m[0;34m([0m[0mkind[0m[0;34m,[0m [0mrequest[0m[0;34m)[0m[0;34m[0m[0m
[0m[1;32m    958[0m         [0;32mreturn[0m [0mself[0m[0;34m.[0m[0m_get_operation[0m[0;34m([0m[0mresp[0m[0;34m.[0m[0moperationHandle[0m[0;34m)[0m[0;34m[0m[0m
[1;32m    959[0m [0;34m[0m[0m

[0;32m~/venv/lib/python3.5/site-packages/impala/hiveserver2.py[0m in [0;36m_rpc[0;34m(self, func_name, request)[0m
[1;32m    923[0m         [0mresponse[0m [0;34m=[0m [0mself[0m[0;34m.[0m[0m_execute[0m[0;34m([0m[0mfunc_name[0m[0;34m,[0m [0mrequest[0m[0;34m)[0m[0;34m[0m[0m
[1;32m    924[0m         [0mself[0m[0;34m.[0m[0m_log_response[0m[0;34m([0m[0mfunc_name[0m[0;34m,[0m [0mresponse[0m[0;34m)[0m[0;34m[0m[0m
[0;32m--> 925[0;31m         [0merr_if_rpc_not_ok[0m[0;34m([0m[0mresponse[0m[0;34m)[0m[0;34m[0m[0m
[0m[1;32m    926[0m         [0;32mreturn[0m [0mresponse[0m[0;34m[0m[0m
[1;32m    927[0m [0;34m[0m[0m

[0;32m~/venv/lib/python3.5/site-packages/impala/hiveserver2.py[0m in [0;36merr_if_rpc_not_ok[0;34m(resp)[0m
[1;32m    702[0m             [0mresp[0m[0;34m.[0m[0mstatus[0m[0;34m.[0m[0mstatusCode[0m [0;34m!=[0m [0mTStatusCode[0m[0;34m.[0m[0mSUCCESS_WITH_INFO_STATUS[0m [0;32mand[0m[0;34m[0m[0m
[1;32m    703[0m             resp.status.statusCode != TStatusCode.STILL_EXECUTING_STATUS):
[0;32m--> 704[0;31m         [0;32mraise[0m [0mHiveServer2Error[0m[0;34m([0m[0mresp[0m[0;34m.[0m[0mstatus[0m[0;34m.[0m[0merrorMessage[0m[0;34m)[0m[0;34m[0m[0m
[0m[1;32m    705[0m [0;34m[0m[0m
[1;32m    706[0m [0;34m[0m[0m

[0;31mHiveServer2Error[0m: Error while compiling statement: FAILED: ParseException line 3:21 missing \' at ',' near '<EOF>'
HiveServer2Error: Error while compiling statement: FAILED: ParseException line 3:21 missing \' at ',' near '<EOF>'

Sun Sep  8 07:38:01 UTC 2019
Refreshing report01a
[NbConvertApp] Converting notebook 01a-editor-month-table.ipynb to notebook
[NbConvertApp] Executing notebook with kernel: python3
[NbConvertApp] Writing 254222 bytes to 01a-editor-month-table.ipynb
Mon Sep  9 03:00:01 UTC 2019
Refreshing 01atable
[NbConvertApp] Converting notebook 01a-editor-month-table.ipynb to notebook
[NbConvertApp] Executing notebook with kernel: python3
[NbConvertApp] Writing 254222 bytes to 01a-editor-month-table.ipynb
Refreshing 01btable
[NbConvertApp] Converting notebook 01b-new-editor-table.ipynb to notebook
[NbConvertApp] Executing notebook with kernel: python3
[NbConvertApp] Writing 111103 bytes to 01b-new-editor-table.ipynb
Refreshing 02calculation
[NbConvertApp] Converting notebook 02-calculation.ipynb to notebook
[NbConvertApp] Executing notebook with kernel: python3
[NbConvertApp] ERROR | Error while converting '02-calculation.ipynb'
Traceback (most recent call last):
  File "/home/conniecc1/venv/lib/python3.5/site-packages/nbconvert/nbconvertapp.py", line 393, in export_single_notebook
    output, resources = self.exporter.from_filename(notebook_filename, resources=resources)
  File "/home/conniecc1/venv/lib/python3.5/site-packages/nbconvert/exporters/exporter.py", line 174, in from_filename
    return self.from_file(f, resources=resources, **kw)
  File "/home/conniecc1/venv/lib/python3.5/site-packages/nbconvert/exporters/exporter.py", line 192, in from_file
    return self.from_notebook_node(nbformat.read(file_stream, as_version=4), resources=resources, **kw)
  File "/home/conniecc1/venv/lib/python3.5/site-packages/nbconvert/exporters/notebook.py", line 31, in from_notebook_node
    nb_copy, resources = super(NotebookExporter, self).from_notebook_node(nb, resources, **kw)
  File "/home/conniecc1/venv/lib/python3.5/site-packages/nbconvert/exporters/exporter.py", line 134, in from_notebook_node
    nb_copy, resources = self._preprocess(nb_copy, resources)
  File "/home/conniecc1/venv/lib/python3.5/site-packages/nbconvert/exporters/exporter.py", line 311, in _preprocess
    nbc, resc = preprocessor(nbc, resc)
  File "/home/conniecc1/venv/lib/python3.5/site-packages/nbconvert/preprocessors/base.py", line 47, in __call__
    return self.preprocess(nb, resources)
  File "/home/conniecc1/venv/lib/python3.5/site-packages/nbconvert/preprocessors/execute.py", line 262, in preprocess
    nb, resources = super(ExecutePreprocessor, self).preprocess(nb, resources)
  File "/home/conniecc1/venv/lib/python3.5/site-packages/nbconvert/preprocessors/base.py", line 69, in preprocess
    nb.cells[index], resources = self.preprocess_cell(cell, resources, index)
  File "/home/conniecc1/venv/lib/python3.5/site-packages/nbconvert/preprocessors/execute.py", line 286, in preprocess_cell
    raise CellExecutionError.from_cell_and_msg(cell, out)
nbconvert.preprocessors.execute.CellExecutionError: An error occurred while executing the following cell:
------------------
total_new = get_new_pages().rename(columns={"new_pages": "net_new_content_pages"})
api_results.append(total_new)
------------------

[0;31m---------------------------------------------------------------------------[0m
[0;31mTimeoutError[0m                              Traceback (most recent call last)
[0;32m~/venv/lib/python3.5/site-packages/urllib3/connection.py[0m in [0;36m_new_conn[0;34m(self)[0m
[1;32m    170[0m             conn = connection.create_connection(
[0;32m--> 171[0;31m                 (self._dns_host, self.port), self.timeout, **extra_kw)
[0m[1;32m    172[0m [0;34m[0m[0m

[0;32m~/venv/lib/python3.5/site-packages/urllib3/util/connection.py[0m in [0;36mcreate_connection[0;34m(address, timeout, source_address, socket_options)[0m
[1;32m     78[0m     [0;32mif[0m [0merr[0m [0;32mis[0m [0;32mnot[0m [0;32mNone[0m[0;34m:[0m[0;34m[0m[0m
[0;32m---> 79[0;31m         [0;32mraise[0m [0merr[0m[0;34m[0m[0m
[0m[1;32m     80[0m [0;34m[0m[0m

[0;32m~/venv/lib/python3.5/site-packages/urllib3/util/connection.py[0m in [0;36mcreate_connection[0;34m(address, timeout, source_address, socket_options)[0m
[1;32m     68[0m                 [0msock[0m[0;34m.[0m[0mbind[0m[0;34m([0m[0msource_address[0m[0;34m)[0m[0;34m[0m[0m
[0;32m---> 69[0;31m             [0msock[0m[0;34m.[0m[0mconnect[0m[0;34m([0m[0msa[0m[0;34m)[0m[0;34m[0m[0m
[0m[1;32m     70[0m             [0;32mreturn[0m [0msock[0m[0;34m[0m[0m

[0;31mTimeoutError[0m: [Errno 110] Connection timed out

During handling of the above exception, another exception occurred:

[0;31mNewConnectionError[0m                        Traceback (most recent call last)
[0;32m~/venv/lib/python3.5/site-packages/urllib3/connectionpool.py[0m in [0;36murlopen[0;34m(self, method, url, body, headers, retries, redirect, assert_same_host, timeout, pool_timeout, release_conn, chunked, body_pos, **response_kw)[0m
[1;32m    599[0m                                                   [0mbody[0m[0;34m=[0m[0mbody[0m[0;34m,[0m [0mheaders[0m[0;34m=[0m[0mheaders[0m[0;34m,[0m[0;34m[0m[0m
[0;32m--> 600[0;31m                                                   chunked=chunked)
[0m[1;32m    601[0m [0;34m[0m[0m

[0;32m~/venv/lib/python3.5/site-packages/urllib3/connectionpool.py[0m in [0;36m_make_request[0;34m(self, conn, method, url, timeout, chunked, **httplib_request_kw)[0m
[1;32m    353[0m         [0;32melse[0m[0;34m:[0m[0;34m[0m[0m
[0;32m--> 354[0;31m             [0mconn[0m[0;34m.[0m[0mrequest[0m[0;34m([0m[0mmethod[0m[0;34m,[0m [0murl[0m[0;34m,[0m [0;34m**[0m[0mhttplib_request_kw[0m[0;34m)[0m[0;34m[0m[0m
[0m[1;32m    355[0m [0;34m[0m[0m

[0;32m/usr/lib/python3.5/http/client.py[0m in [0;36mrequest[0;34m(self, method, url, body, headers)[0m
[1;32m   1106[0m         [0;34m"""Send a complete request to the server."""[0m[0;34m[0m[0m
[0;32m-> 1107[0;31m         [0mself[0m[0;34m.[0m[0m_send_request[0m[0;34m([0m[0mmethod[0m[0;34m,[0m [0murl[0m[0;34m,[0m [0mbody[0m[0;34m,[0m [0mheaders[0m[0;34m)[0m[0;34m[0m[0m
[0m[1;32m   1108[0m [0;34m[0m[0m

[0;32m/usr/lib/python3.5/http/client.py[0m in [0;36m_send_request[0;34m(self, method, url, body, headers)[0m
[1;32m   1151[0m             [0mbody[0m [0;34m=[0m [0m_encode[0m[0;34m([0m[0mbody[0m[0;34m,[0m [0;34m'body'[0m[0;34m)[0m[0;34m[0m[0m
[0;32m-> 1152[0;31m         [0mself[0m[0;34m.[0m[0mendheaders[0m[0;34m([0m[0mbody[0m[0;34m)[0m[0;34m[0m[0m
[0m[1;32m   1153[0m [0;34m[0m[0m

[0;32m/usr/lib/python3.5/http/client.py[0m in [0;36mendheaders[0;34m(self, message_body)[0m
[1;32m   1102[0m             [0;32mraise[0m [0mCannotSendHeader[0m[0;34m([0m[0;34m)[0m[0;34m[0m[0m
[0;32m-> 1103[0;31m         [0mself[0m[0;34m.[0m[0m_send_output[0m[0;34m([0m[0mmessage_body[0m[0;34m)[0m[0;34m[0m[0m
[0m[1;32m   1104[0m [0;34m[0m[0m

[0;32m/usr/lib/python3.5/http/client.py[0m in [0;36m_send_output[0;34m(self, message_body)[0m
[1;32m    933[0m [0;34m[0m[0m
[0;32m--> 934[0;31m         [0mself[0m[0;34m.[0m[0msend[0m[0;34m([0m[0mmsg[0m[0;34m)[0m[0;34m[0m[0m
[0m[1;32m    935[0m         [0;32mif[0m [0mmessage_body[0m [0;32mis[0m [0;32mnot[0m [0;32mNone[0m[0;34m:[0m[0;34m[0m[0m

[0;32m/usr/lib/python3.5/http/client.py[0m in [0;36msend[0;34m(self, data)[0m
[1;32m    876[0m             [0;32mif[0m [0mself[0m[0;34m.[0m[0mauto_open[0m[0;34m:[0m[0;34m[0m[0m
[0;32m--> 877[0;31m                 [0mself[0m[0;34m.[0m[0mconnect[0m[0;34m([0m[0;34m)[0m[0;34m[0m[0m
[0m[1;32m    878[0m             [0;32melse[0m[0;34m:[0m[0;34m[0m[0m

[0;32m~/venv/lib/python3.5/site-packages/urllib3/connection.py[0m in [0;36mconnect[0;34m(self)[0m
[1;32m    195[0m     [0;32mdef[0m [0mconnect[0m[0;34m([0m[0mself[0m[0;34m)[0m[0;34m:[0m[0;34m[0m[0m
[0;32m--> 196[0;31m         [0mconn[0m [0;34m=[0m [0mself[0m[0;34m.[0m[0m_new_conn[0m[0;34m([0m[0;34m)[0m[0;34m[0m[0m
[0m[1;32m    197[0m         [0mself[0m[0;34m.[0m[0m_prepare_conn[0m[0;34m([0m[0mconn[0m[0;34m)[0m[0;34m[0m[0m

[0;32m~/venv/lib/python3.5/site-packages/urllib3/connection.py[0m in [0;36m_new_conn[0;34m(self)[0m
[1;32m    179[0m             raise NewConnectionError(
[0;32m--> 180[0;31m                 self, "Failed to establish a new connection: %s" % e)
[0m[1;32m    181[0m [0;34m[0m[0m

[0;31mNewConnectionError[0m: <urllib3.connection.HTTPConnection object at 0x7fc2ebc89a90>: Failed to establish a new connection: [Errno 110] Connection timed out

During handling of the above exception, another exception occurred:

[0;31mMaxRetryError[0m                             Traceback (most recent call last)
[0;32m~/venv/lib/python3.5/site-packages/requests/adapters.py[0m in [0;36msend[0;34m(self, request, stream, timeout, verify, cert, proxies)[0m
[1;32m    444[0m                     [0mretries[0m[0;34m=[0m[0mself[0m[0;34m.[0m[0mmax_retries[0m[0;34m,[0m[0;34m[0m[0m
[0;32m--> 445[0;31m                     [0mtimeout[0m[0;34m=[0m[0mtimeout[0m[0;34m[0m[0m
[0m[1;32m    446[0m                 )

[0;32m~/venv/lib/python3.5/site-packages/urllib3/connectionpool.py[0m in [0;36murlopen[0;34m(self, method, url, body, headers, retries, redirect, assert_same_host, timeout, pool_timeout, release_conn, chunked, body_pos, **response_kw)[0m
[1;32m    637[0m             retries = retries.increment(method, url, error=e, _pool=self,
[0;32m--> 638[0;31m                                         _stacktrace=sys.exc_info()[2])
[0m[1;32m    639[0m             [0mretries[0m[0;34m.[0m[0msleep[0m[0;34m([0m[0;34m)[0m[0;34m[0m[0m

[0;32m~/venv/lib/python3.5/site-packages/urllib3/util/retry.py[0m in [0;36mincrement[0;34m(self, method, url, response, error, _pool, _stacktrace)[0m
[1;32m    397[0m         [0;32mif[0m [0mnew_retry[0m[0;34m.[0m[0mis_exhausted[0m[0;34m([0m[0;34m)[0m[0;34m:[0m[0;34m[0m[0m
[0;32m--> 398[0;31m             [0;32mraise[0m [0mMaxRetryError[0m[0;34m([0m[0m_pool[0m[0;34m,[0m [0murl[0m[0;34m,[0m [0merror[0m [0;32mor[0m [0mResponseError[0m[0;34m([0m[0mcause[0m[0;34m)[0m[0;34m)[0m[0;34m[0m[0m
[0m[1;32m    399[0m [0;34m[0m[0m

[0;31mMaxRetryError[0m: HTTPConnectionPool(host='aqs1004.eqiad.wmnet', port=7232): Max retries exceeded with url: /analytics.wikimedia.org/v1/edited-pages/new/all-projects/all-editor-types/content/monthly/20190801/20190901 (Caused by NewConnectionError('<urllib3.connection.HTTPConnection object at 0x7fc2ebc89a90>: Failed to establish a new connection: [Errno 110] Connection timed out',))

During handling of the above exception, another exception occurred:

[0;31mConnectionError[0m                           Traceback (most recent call last)
[0;32m<ipython-input-6-e7ab8219e6d0>[0m in [0;36m<module>[0;34m()[0m
[0;32m----> 1[0;31m [0mtotal_new[0m [0;34m=[0m [0mget_new_pages[0m[0;34m([0m[0;34m)[0m[0;34m.[0m[0mrename[0m[0;34m([0m[0mcolumns[0m[0;34m=[0m[0;34m{[0m[0;34m"new_pages"[0m[0;34m:[0m [0;34m"net_new_content_pages"[0m[0;34m}[0m[0;34m)[0m[0;34m[0m[0m
[0m[1;32m      2[0m [0mapi_results[0m[0;34m.[0m[0mappend[0m[0;34m([0m[0mtotal_new[0m[0;34m)[0m[0;34m[0m[0m

[0;32m<ipython-input-5-bb040ed954cf>[0m in [0;36mget_new_pages[0;34m(project, page_type, start, end)[0m
[1;32m     25[0m     )
[1;32m     26[0m [0;34m[0m[0m
[0;32m---> 27[0;31m     [0mr[0m [0;34m=[0m [0mrequests[0m[0;34m.[0m[0mget[0m[0;34m([0m[0murl[0m[0;34m,[0m [0mheaders[0m[0;34m=[0m[0mheaders[0m[0;34m)[0m[0;34m[0m[0m
[0m[1;32m     28[0m     [0mdata[0m [0;34m=[0m [0mr[0m[0;34m.[0m[0mjson[0m[0;34m([0m[0;34m)[0m[0;34m[[0m[0;34m"items"[0m[0;34m][0m[0;34m[[0m[0;36m0[0m[0;34m][0m[0;34m[[0m[0;34m"results"[0m[0;34m][0m[0;34m[0m[0m
[1;32m     29[0m     [0mframe[0m [0;34m=[0m [0mpd[0m[0;34m.[0m[0mDataFrame[0m[0;34m([0m[0mdata[0m[0;34m)[0m[0;34m[0m[0m

[0;32m~/venv/lib/python3.5/site-packages/requests/api.py[0m in [0;36mget[0;34m(url, params, **kwargs)[0m
[1;32m     70[0m [0;34m[0m[0m
[1;32m     71[0m     [0mkwargs[0m[0;34m.[0m[0msetdefault[0m[0;34m([0m[0;34m'allow_redirects'[0m[0;34m,[0m [0;32mTrue[0m[0;34m)[0m[0;34m[0m[0m
[0;32m---> 72[0;31m     [0;32mreturn[0m [0mrequest[0m[0;34m([0m[0;34m'get'[0m[0;34m,[0m [0murl[0m[0;34m,[0m [0mparams[0m[0;34m=[0m[0mparams[0m[0;34m,[0m [0;34m**[0m[0mkwargs[0m[0;34m)[0m[0;34m[0m[0m
[0m[1;32m     73[0m [0;34m[0m[0m
[1;32m     74[0m [0;34m[0m[0m

[0;32m~/venv/lib/python3.5/site-packages/requests/api.py[0m in [0;36mrequest[0;34m(method, url, **kwargs)[0m
[1;32m     56[0m     [0;31m# cases, and look like a memory leak in others.[0m[0;34m[0m[0;34m[0m[0m
[1;32m     57[0m     [0;32mwith[0m [0msessions[0m[0;34m.[0m[0mSession[0m[0;34m([0m[0;34m)[0m [0;32mas[0m [0msession[0m[0;34m:[0m[0;34m[0m[0m
[0;32m---> 58[0;31m         [0;32mreturn[0m [0msession[0m[0;34m.[0m[0mrequest[0m[0;34m([0m[0mmethod[0m[0;34m=[0m[0mmethod[0m[0;34m,[0m [0murl[0m[0;34m=[0m[0murl[0m[0;34m,[0m [0;34m**[0m[0mkwargs[0m[0;34m)[0m[0;34m[0m[0m
[0m[1;32m     59[0m [0;34m[0m[0m
[1;32m     60[0m [0;34m[0m[0m

[0;32m~/venv/lib/python3.5/site-packages/requests/sessions.py[0m in [0;36mrequest[0;34m(self, method, url, params, data, headers, cookies, files, auth, timeout, allow_redirects, proxies, hooks, stream, verify, cert, json)[0m
[1;32m    510[0m         }
[1;32m    511[0m         [0msend_kwargs[0m[0;34m.[0m[0mupdate[0m[0;34m([0m[0msettings[0m[0;34m)[0m[0;34m[0m[0m
[0;32m--> 512[0;31m         [0mresp[0m [0;34m=[0m [0mself[0m[0;34m.[0m[0msend[0m[0;34m([0m[0mprep[0m[0;34m,[0m [0;34m**[0m[0msend_kwargs[0m[0;34m)[0m[0;34m[0m[0m
[0m[1;32m    513[0m [0;34m[0m[0m
[1;32m    514[0m         [0;32mreturn[0m [0mresp[0m[0;34m[0m[0m

[0;32m~/venv/lib/python3.5/site-packages/requests/sessions.py[0m in [0;36msend[0;34m(self, request, **kwargs)[0m
[1;32m    620[0m [0;34m[0m[0m
[1;32m    621[0m         [0;31m# Send the request[0m[0;34m[0m[0;34m[0m[0m
[0;32m--> 622[0;31m         [0mr[0m [0;34m=[0m [0madapter[0m[0;34m.[0m[0msend[0m[0;34m([0m[0mrequest[0m[0;34m,[0m [0;34m**[0m[0mkwargs[0m[0;34m)[0m[0;34m[0m[0m
[0m[1;32m    623[0m [0;34m[0m[0m
[1;32m    624[0m         [0;31m# Total elapsed time of the request (approximately)[0m[0;34m[0m[0;34m[0m[0m

[0;32m~/venv/lib/python3.5/site-packages/requests/adapters.py[0m in [0;36msend[0;34m(self, request, stream, timeout, verify, cert, proxies)[0m
[1;32m    511[0m                 [0;32mraise[0m [0mSSLError[0m[0;34m([0m[0me[0m[0;34m,[0m [0mrequest[0m[0;34m=[0m[0mrequest[0m[0;34m)[0m[0;34m[0m[0m
[1;32m    512[0m [0;34m[0m[0m
[0;32m--> 513[0;31m             [0;32mraise[0m [0mConnectionError[0m[0;34m([0m[0me[0m[0;34m,[0m [0mrequest[0m[0;34m=[0m[0mrequest[0m[0;34m)[0m[0;34m[0m[0m
[0m[1;32m    514[0m [0;34m[0m[0m
[1;32m    515[0m         [0;32mexcept[0m [0mClosedPoolError[0m [0;32mas[0m [0me[0m[0;34m:[0m[0;34m[0m[0m

[0;31mConnectionError[0m: HTTPConnectionPool(host='aqs1004.eqiad.wmnet', port=7232): Max retries exceeded with url: /analytics.wikimedia.org/v1/edited-pages/new/all-projects/all-editor-types/content/monthly/20190801/20190901 (Caused by NewConnectionError('<urllib3.connection.HTTPConnection object at 0x7fc2ebc89a90>: Failed to establish a new connection: [Errno 110] Connection timed out',))
ConnectionError: HTTPConnectionPool(host='aqs1004.eqiad.wmnet', port=7232): Max retries exceeded with url: /analytics.wikimedia.org/v1/edited-pages/new/all-projects/all-editor-types/content/monthly/20190801/20190901 (Caused by NewConnectionError('<urllib3.connection.HTTPConnection object at 0x7fc2ebc89a90>: Failed to establish a new connection: [Errno 110] Connection timed out',))

Mon Sep  9 07:00:01 UTC 2019
Refreshing 02calculation
[NbConvertApp] Converting notebook 02-calculation.ipynb to notebook
[NbConvertApp] Executing notebook with kernel: python3
[NbConvertApp] ERROR | Error while converting '02-calculation.ipynb'
Traceback (most recent call last):
  File "/home/conniecc1/venv/lib/python3.5/site-packages/nbconvert/nbconvertapp.py", line 393, in export_single_notebook
    output, resources = self.exporter.from_filename(notebook_filename, resources=resources)
  File "/home/conniecc1/venv/lib/python3.5/site-packages/nbconvert/exporters/exporter.py", line 174, in from_filename
    return self.from_file(f, resources=resources, **kw)
  File "/home/conniecc1/venv/lib/python3.5/site-packages/nbconvert/exporters/exporter.py", line 192, in from_file
    return self.from_notebook_node(nbformat.read(file_stream, as_version=4), resources=resources, **kw)
  File "/home/conniecc1/venv/lib/python3.5/site-packages/nbconvert/exporters/notebook.py", line 31, in from_notebook_node
    nb_copy, resources = super(NotebookExporter, self).from_notebook_node(nb, resources, **kw)
  File "/home/conniecc1/venv/lib/python3.5/site-packages/nbconvert/exporters/exporter.py", line 134, in from_notebook_node
    nb_copy, resources = self._preprocess(nb_copy, resources)
  File "/home/conniecc1/venv/lib/python3.5/site-packages/nbconvert/exporters/exporter.py", line 311, in _preprocess
    nbc, resc = preprocessor(nbc, resc)
  File "/home/conniecc1/venv/lib/python3.5/site-packages/nbconvert/preprocessors/base.py", line 47, in __call__
    return self.preprocess(nb, resources)
  File "/home/conniecc1/venv/lib/python3.5/site-packages/nbconvert/preprocessors/execute.py", line 262, in preprocess
    nb, resources = super(ExecutePreprocessor, self).preprocess(nb, resources)
  File "/home/conniecc1/venv/lib/python3.5/site-packages/nbconvert/preprocessors/base.py", line 69, in preprocess
    nb.cells[index], resources = self.preprocess_cell(cell, resources, index)
  File "/home/conniecc1/venv/lib/python3.5/site-packages/nbconvert/preprocessors/execute.py", line 286, in preprocess_cell
    raise CellExecutionError.from_cell_and_msg(cell, out)
nbconvert.preprocessors.execute.CellExecutionError: An error occurred while executing the following cell:
------------------
total_new = get_new_pages().rename(columns={"new_pages": "net_new_content_pages"})
api_results.append(total_new)
------------------

[0;31m---------------------------------------------------------------------------[0m
[0;31mTimeoutError[0m                              Traceback (most recent call last)
[0;32m~/venv/lib/python3.5/site-packages/urllib3/connection.py[0m in [0;36m_new_conn[0;34m(self)[0m
[1;32m    170[0m             conn = connection.create_connection(
[0;32m--> 171[0;31m                 (self._dns_host, self.port), self.timeout, **extra_kw)
[0m[1;32m    172[0m [0;34m[0m[0m

[0;32m~/venv/lib/python3.5/site-packages/urllib3/util/connection.py[0m in [0;36mcreate_connection[0;34m(address, timeout, source_address, socket_options)[0m
[1;32m     78[0m     [0;32mif[0m [0merr[0m [0;32mis[0m [0;32mnot[0m [0;32mNone[0m[0;34m:[0m[0;34m[0m[0m
[0;32m---> 79[0;31m         [0;32mraise[0m [0merr[0m[0;34m[0m[0m
[0m[1;32m     80[0m [0;34m[0m[0m

[0;32m~/venv/lib/python3.5/site-packages/urllib3/util/connection.py[0m in [0;36mcreate_connection[0;34m(address, timeout, source_address, socket_options)[0m
[1;32m     68[0m                 [0msock[0m[0;34m.[0m[0mbind[0m[0;34m([0m[0msource_address[0m[0;34m)[0m[0;34m[0m[0m
[0;32m---> 69[0;31m             [0msock[0m[0;34m.[0m[0mconnect[0m[0;34m([0m[0msa[0m[0;34m)[0m[0;34m[0m[0m
[0m[1;32m     70[0m             [0;32mreturn[0m [0msock[0m[0;34m[0m[0m

[0;31mTimeoutError[0m: [Errno 110] Connection timed out

During handling of the above exception, another exception occurred:

[0;31mNewConnectionError[0m                        Traceback (most recent call last)
[0;32m~/venv/lib/python3.5/site-packages/urllib3/connectionpool.py[0m in [0;36murlopen[0;34m(self, method, url, body, headers, retries, redirect, assert_same_host, timeout, pool_timeout, release_conn, chunked, body_pos, **response_kw)[0m
[1;32m    599[0m                                                   [0mbody[0m[0;34m=[0m[0mbody[0m[0;34m,[0m [0mheaders[0m[0;34m=[0m[0mheaders[0m[0;34m,[0m[0;34m[0m[0m
[0;32m--> 600[0;31m                                                   chunked=chunked)
[0m[1;32m    601[0m [0;34m[0m[0m

[0;32m~/venv/lib/python3.5/site-packages/urllib3/connectionpool.py[0m in [0;36m_make_request[0;34m(self, conn, method, url, timeout, chunked, **httplib_request_kw)[0m
[1;32m    353[0m         [0;32melse[0m[0;34m:[0m[0;34m[0m[0m
[0;32m--> 354[0;31m             [0mconn[0m[0;34m.[0m[0mrequest[0m[0;34m([0m[0mmethod[0m[0;34m,[0m [0murl[0m[0;34m,[0m [0;34m**[0m[0mhttplib_request_kw[0m[0;34m)[0m[0;34m[0m[0m
[0m[1;32m    355[0m [0;34m[0m[0m

[0;32m/usr/lib/python3.5/http/client.py[0m in [0;36mrequest[0;34m(self, method, url, body, headers)[0m
[1;32m   1106[0m         [0;34m"""Send a complete request to the server."""[0m[0;34m[0m[0m
[0;32m-> 1107[0;31m         [0mself[0m[0;34m.[0m[0m_send_request[0m[0;34m([0m[0mmethod[0m[0;34m,[0m [0murl[0m[0;34m,[0m [0mbody[0m[0;34m,[0m [0mheaders[0m[0;34m)[0m[0;34m[0m[0m
[0m[1;32m   1108[0m [0;34m[0m[0m

[0;32m/usr/lib/python3.5/http/client.py[0m in [0;36m_send_request[0;34m(self, method, url, body, headers)[0m
[1;32m   1151[0m             [0mbody[0m [0;34m=[0m [0m_encode[0m[0;34m([0m[0mbody[0m[0;34m,[0m [0;34m'body'[0m[0;34m)[0m[0;34m[0m[0m
[0;32m-> 1152[0;31m         [0mself[0m[0;34m.[0m[0mendheaders[0m[0;34m([0m[0mbody[0m[0;34m)[0m[0;34m[0m[0m
[0m[1;32m   1153[0m [0;34m[0m[0m

[0;32m/usr/lib/python3.5/http/client.py[0m in [0;36mendheaders[0;34m(self, message_body)[0m
[1;32m   1102[0m             [0;32mraise[0m [0mCannotSendHeader[0m[0;34m([0m[0;34m)[0m[0;34m[0m[0m
[0;32m-> 1103[0;31m         [0mself[0m[0;34m.[0m[0m_send_output[0m[0;34m([0m[0mmessage_body[0m[0;34m)[0m[0;34m[0m[0m
[0m[1;32m   1104[0m [0;34m[0m[0m

[0;32m/usr/lib/python3.5/http/client.py[0m in [0;36m_send_output[0;34m(self, message_body)[0m
[1;32m    933[0m [0;34m[0m[0m
[0;32m--> 934[0;31m         [0mself[0m[0;34m.[0m[0msend[0m[0;34m([0m[0mmsg[0m[0;34m)[0m[0;34m[0m[0m
[0m[1;32m    935[0m         [0;32mif[0m [0mmessage_body[0m [0;32mis[0m [0;32mnot[0m [0;32mNone[0m[0;34m:[0m[0;34m[0m[0m

[0;32m/usr/lib/python3.5/http/client.py[0m in [0;36msend[0;34m(self, data)[0m
[1;32m    876[0m             [0;32mif[0m [0mself[0m[0;34m.[0m[0mauto_open[0m[0;34m:[0m[0;34m[0m[0m
[0;32m--> 877[0;31m                 [0mself[0m[0;34m.[0m[0mconnect[0m[0;34m([0m[0;34m)[0m[0;34m[0m[0m
[0m[1;32m    878[0m             [0;32melse[0m[0;34m:[0m[0;34m[0m[0m

[0;32m~/venv/lib/python3.5/site-packages/urllib3/connection.py[0m in [0;36mconnect[0;34m(self)[0m
[1;32m    195[0m     [0;32mdef[0m [0mconnect[0m[0;34m([0m[0mself[0m[0;34m)[0m[0;34m:[0m[0;34m[0m[0m
[0;32m--> 196[0;31m         [0mconn[0m [0;34m=[0m [0mself[0m[0;34m.[0m[0m_new_conn[0m[0;34m([0m[0;34m)[0m[0;34m[0m[0m
[0m[1;32m    197[0m         [0mself[0m[0;34m.[0m[0m_prepare_conn[0m[0;34m([0m[0mconn[0m[0;34m)[0m[0;34m[0m[0m

[0;32m~/venv/lib/python3.5/site-packages/urllib3/connection.py[0m in [0;36m_new_conn[0;34m(self)[0m
[1;32m    179[0m             raise NewConnectionError(
[0;32m--> 180[0;31m                 self, "Failed to establish a new connection: %s" % e)
[0m[1;32m    181[0m [0;34m[0m[0m

[0;31mNewConnectionError[0m: <urllib3.connection.HTTPConnection object at 0x7fb585ef5588>: Failed to establish a new connection: [Errno 110] Connection timed out

During handling of the above exception, another exception occurred:

[0;31mMaxRetryError[0m                             Traceback (most recent call last)
[0;32m~/venv/lib/python3.5/site-packages/requests/adapters.py[0m in [0;36msend[0;34m(self, request, stream, timeout, verify, cert, proxies)[0m
[1;32m    444[0m                     [0mretries[0m[0;34m=[0m[0mself[0m[0;34m.[0m[0mmax_retries[0m[0;34m,[0m[0;34m[0m[0m
[0;32m--> 445[0;31m                     [0mtimeout[0m[0;34m=[0m[0mtimeout[0m[0;34m[0m[0m
[0m[1;32m    446[0m                 )

[0;32m~/venv/lib/python3.5/site-packages/urllib3/connectionpool.py[0m in [0;36murlopen[0;34m(self, method, url, body, headers, retries, redirect, assert_same_host, timeout, pool_timeout, release_conn, chunked, body_pos, **response_kw)[0m
[1;32m    637[0m             retries = retries.increment(method, url, error=e, _pool=self,
[0;32m--> 638[0;31m                                         _stacktrace=sys.exc_info()[2])
[0m[1;32m    639[0m             [0mretries[0m[0;34m.[0m[0msleep[0m[0;34m([0m[0;34m)[0m[0;34m[0m[0m

[0;32m~/venv/lib/python3.5/site-packages/urllib3/util/retry.py[0m in [0;36mincrement[0;34m(self, method, url, response, error, _pool, _stacktrace)[0m
[1;32m    397[0m         [0;32mif[0m [0mnew_retry[0m[0;34m.[0m[0mis_exhausted[0m[0;34m([0m[0;34m)[0m[0;34m:[0m[0;34m[0m[0m
[0;32m--> 398[0;31m             [0;32mraise[0m [0mMaxRetryError[0m[0;34m([0m[0m_pool[0m[0;34m,[0m [0murl[0m[0;34m,[0m [0merror[0m [0;32mor[0m [0mResponseError[0m[0;34m([0m[0mcause[0m[0;34m)[0m[0;34m)[0m[0;34m[0m[0m
[0m[1;32m    399[0m [0;34m[0m[0m

[0;31mMaxRetryError[0m: HTTPConnectionPool(host='aqs1004.eqiad.wmnet', port=7232): Max retries exceeded with url: /analytics.wikimedia.org/v1/edited-pages/new/all-projects/all-editor-types/content/monthly/20190801/20190901 (Caused by NewConnectionError('<urllib3.connection.HTTPConnection object at 0x7fb585ef5588>: Failed to establish a new connection: [Errno 110] Connection timed out',))

During handling of the above exception, another exception occurred:

[0;31mConnectionError[0m                           Traceback (most recent call last)
[0;32m<ipython-input-6-e7ab8219e6d0>[0m in [0;36m<module>[0;34m()[0m
[0;32m----> 1[0;31m [0mtotal_new[0m [0;34m=[0m [0mget_new_pages[0m[0;34m([0m[0;34m)[0m[0;34m.[0m[0mrename[0m[0;34m([0m[0mcolumns[0m[0;34m=[0m[0;34m{[0m[0;34m"new_pages"[0m[0;34m:[0m [0;34m"net_new_content_pages"[0m[0;34m}[0m[0;34m)[0m[0;34m[0m[0m
[0m[1;32m      2[0m [0mapi_results[0m[0;34m.[0m[0mappend[0m[0;34m([0m[0mtotal_new[0m[0;34m)[0m[0;34m[0m[0m

[0;32m<ipython-input-5-bb040ed954cf>[0m in [0;36mget_new_pages[0;34m(project, page_type, start, end)[0m
[1;32m     25[0m     )
[1;32m     26[0m [0;34m[0m[0m
[0;32m---> 27[0;31m     [0mr[0m [0;34m=[0m [0mrequests[0m[0;34m.[0m[0mget[0m[0;34m([0m[0murl[0m[0;34m,[0m [0mheaders[0m[0;34m=[0m[0mheaders[0m[0;34m)[0m[0;34m[0m[0m
[0m[1;32m     28[0m     [0mdata[0m [0;34m=[0m [0mr[0m[0;34m.[0m[0mjson[0m[0;34m([0m[0;34m)[0m[0;34m[[0m[0;34m"items"[0m[0;34m][0m[0;34m[[0m[0;36m0[0m[0;34m][0m[0;34m[[0m[0;34m"results"[0m[0;34m][0m[0;34m[0m[0m
[1;32m     29[0m     [0mframe[0m [0;34m=[0m [0mpd[0m[0;34m.[0m[0mDataFrame[0m[0;34m([0m[0mdata[0m[0;34m)[0m[0;34m[0m[0m

[0;32m~/venv/lib/python3.5/site-packages/requests/api.py[0m in [0;36mget[0;34m(url, params, **kwargs)[0m
[1;32m     70[0m [0;34m[0m[0m
[1;32m     71[0m     [0mkwargs[0m[0;34m.[0m[0msetdefault[0m[0;34m([0m[0;34m'allow_redirects'[0m[0;34m,[0m [0;32mTrue[0m[0;34m)[0m[0;34m[0m[0m
[0;32m---> 72[0;31m     [0;32mreturn[0m [0mrequest[0m[0;34m([0m[0;34m'get'[0m[0;34m,[0m [0murl[0m[0;34m,[0m [0mparams[0m[0;34m=[0m[0mparams[0m[0;34m,[0m [0;34m**[0m[0mkwargs[0m[0;34m)[0m[0;34m[0m[0m
[0m[1;32m     73[0m [0;34m[0m[0m
[1;32m     74[0m [0;34m[0m[0m

[0;32m~/venv/lib/python3.5/site-packages/requests/api.py[0m in [0;36mrequest[0;34m(method, url, **kwargs)[0m
[1;32m     56[0m     [0;31m# cases, and look like a memory leak in others.[0m[0;34m[0m[0;34m[0m[0m
[1;32m     57[0m     [0;32mwith[0m [0msessions[0m[0;34m.[0m[0mSession[0m[0;34m([0m[0;34m)[0m [0;32mas[0m [0msession[0m[0;34m:[0m[0;34m[0m[0m
[0;32m---> 58[0;31m         [0;32mreturn[0m [0msession[0m[0;34m.[0m[0mrequest[0m[0;34m([0m[0mmethod[0m[0;34m=[0m[0mmethod[0m[0;34m,[0m [0murl[0m[0;34m=[0m[0murl[0m[0;34m,[0m [0;34m**[0m[0mkwargs[0m[0;34m)[0m[0;34m[0m[0m
[0m[1;32m     59[0m [0;34m[0m[0m
[1;32m     60[0m [0;34m[0m[0m

[0;32m~/venv/lib/python3.5/site-packages/requests/sessions.py[0m in [0;36mrequest[0;34m(self, method, url, params, data, headers, cookies, files, auth, timeout, allow_redirects, proxies, hooks, stream, verify, cert, json)[0m
[1;32m    510[0m         }
[1;32m    511[0m         [0msend_kwargs[0m[0;34m.[0m[0mupdate[0m[0;34m([0m[0msettings[0m[0;34m)[0m[0;34m[0m[0m
[0;32m--> 512[0;31m         [0mresp[0m [0;34m=[0m [0mself[0m[0;34m.[0m[0msend[0m[0;34m([0m[0mprep[0m[0;34m,[0m [0;34m**[0m[0msend_kwargs[0m[0;34m)[0m[0;34m[0m[0m
[0m[1;32m    513[0m [0;34m[0m[0m
[1;32m    514[0m         [0;32mreturn[0m [0mresp[0m[0;34m[0m[0m

[0;32m~/venv/lib/python3.5/site-packages/requests/sessions.py[0m in [0;36msend[0;34m(self, request, **kwargs)[0m
[1;32m    620[0m [0;34m[0m[0m
[1;32m    621[0m         [0;31m# Send the request[0m[0;34m[0m[0;34m[0m[0m
[0;32m--> 622[0;31m         [0mr[0m [0;34m=[0m [0madapter[0m[0;34m.[0m[0msend[0m[0;34m([0m[0mrequest[0m[0;34m,[0m [0;34m**[0m[0mkwargs[0m[0;34m)[0m[0;34m[0m[0m
[0m[1;32m    623[0m [0;34m[0m[0m
[1;32m    624[0m         [0;31m# Total elapsed time of the request (approximately)[0m[0;34m[0m[0;34m[0m[0m

[0;32m~/venv/lib/python3.5/site-packages/requests/adapters.py[0m in [0;36msend[0;34m(self, request, stream, timeout, verify, cert, proxies)[0m
[1;32m    511[0m                 [0;32mraise[0m [0mSSLError[0m[0;34m([0m[0me[0m[0;34m,[0m [0mrequest[0m[0;34m=[0m[0mrequest[0m[0;34m)[0m[0;34m[0m[0m
[1;32m    512[0m [0;34m[0m[0m
[0;32m--> 513[0;31m             [0;32mraise[0m [0mConnectionError[0m[0;34m([0m[0me[0m[0;34m,[0m [0mrequest[0m[0;34m=[0m[0mrequest[0m[0;34m)[0m[0;34m[0m[0m
[0m[1;32m    514[0m [0;34m[0m[0m
[1;32m    515[0m         [0;32mexcept[0m [0mClosedPoolError[0m [0;32mas[0m [0me[0m[0;34m:[0m[0;34m[0m[0m

[0;31mConnectionError[0m: HTTPConnectionPool(host='aqs1004.eqiad.wmnet', port=7232): Max retries exceeded with url: /analytics.wikimedia.org/v1/edited-pages/new/all-projects/all-editor-types/content/monthly/20190801/20190901 (Caused by NewConnectionError('<urllib3.connection.HTTPConnection object at 0x7fb585ef5588>: Failed to establish a new connection: [Errno 110] Connection timed out',))
ConnectionError: HTTPConnectionPool(host='aqs1004.eqiad.wmnet', port=7232): Max retries exceeded with url: /analytics.wikimedia.org/v1/edited-pages/new/all-projects/all-editor-types/content/monthly/20190801/20190901 (Caused by NewConnectionError('<urllib3.connection.HTTPConnection object at 0x7fb585ef5588>: Failed to establish a new connection: [Errno 110] Connection timed out',))

Mon Sep  9 16:45:01 UTC 2019
Refreshing 02calculation
Traceback (most recent call last):
  File "/home/conniecc1/venv/bin/jupyter-nbconvert", line 10, in <module>
    sys.exit(main())
  File "/home/conniecc1/venv/lib/python3.5/site-packages/jupyter_core/application.py", line 266, in launch_instance
    return super(JupyterApp, cls).launch_instance(argv=argv, **kwargs)
  File "/home/conniecc1/venv/lib/python3.5/site-packages/traitlets/config/application.py", line 658, in launch_instance
    app.start()
  File "/home/conniecc1/venv/lib/python3.5/site-packages/nbconvert/nbconvertapp.py", line 325, in start
    self.convert_notebooks()
  File "/home/conniecc1/venv/lib/python3.5/site-packages/nbconvert/nbconvertapp.py", line 483, in convert_notebooks
    self.exporter = cls(config=self.config)
  File "/home/conniecc1/venv/lib/python3.5/site-packages/nbconvert/exporters/exporter.py", line 105, in __init__
    self._init_preprocessors()
  File "/home/conniecc1/venv/lib/python3.5/site-packages/nbconvert/exporters/exporter.py", line 255, in _init_preprocessors
    self.register_preprocessor(preprocessor)
  File "/home/conniecc1/venv/lib/python3.5/site-packages/nbconvert/exporters/exporter.py", line 221, in register_preprocessor
    return self.register_preprocessor(preprocessor_cls, enabled)
  File "/home/conniecc1/venv/lib/python3.5/site-packages/nbconvert/exporters/exporter.py", line 234, in register_preprocessor
    self.register_preprocessor(preprocessor(parent=self), enabled)
  File "/home/conniecc1/venv/lib/python3.5/site-packages/nbconvert/preprocessors/base.py", line 41, in __init__
    super(Preprocessor, self).__init__(**kw)
  File "/home/conniecc1/venv/lib/python3.5/site-packages/nbconvert/utils/base.py", line 29, in __init__
    super(NbConvertBase, self).__init__(**kw)
  File "/home/conniecc1/venv/lib/python3.5/site-packages/traitlets/config/configurable.py", line 84, in __init__
    self.config = config
  File "/home/conniecc1/venv/lib/python3.5/site-packages/traitlets/traitlets.py", line 585, in __set__
    self.set(obj, value)
  File "/home/conniecc1/venv/lib/python3.5/site-packages/traitlets/traitlets.py", line 574, in set
    obj._notify_trait(self.name, old_value, new_value)
  File "/home/conniecc1/venv/lib/python3.5/site-packages/traitlets/traitlets.py", line 1139, in _notify_trait
    type='change',
  File "/home/conniecc1/venv/lib/python3.5/site-packages/traitlets/traitlets.py", line 1176, in notify_change
    c(change)
  File "/home/conniecc1/venv/lib/python3.5/site-packages/traitlets/traitlets.py", line 819, in compatible_observer
    return func(self, change)
  File "/home/conniecc1/venv/lib/python3.5/site-packages/traitlets/config/configurable.py", line 186, in _config_changed
    self._load_config(change.new, traits=traits, section_names=section_names)
  File "/home/conniecc1/venv/lib/python3.5/site-packages/traitlets/config/configurable.py", line 153, in _load_config
    setattr(self, name, deepcopy(config_value))
  File "/home/conniecc1/venv/lib/python3.5/site-packages/traitlets/traitlets.py", line 585, in __set__
    self.set(obj, value)
  File "/home/conniecc1/venv/lib/python3.5/site-packages/traitlets/traitlets.py", line 559, in set
    new_value = self._validate(obj, value)
  File "/home/conniecc1/venv/lib/python3.5/site-packages/traitlets/traitlets.py", line 591, in _validate
    value = self.validate(obj, value)
  File "/home/conniecc1/venv/lib/python3.5/site-packages/traitlets/traitlets.py", line 1870, in validate
    self.error(obj, value)
  File "/home/conniecc1/venv/lib/python3.5/site-packages/traitlets/traitlets.py", line 625, in error
    raise TraitError(e)
traitlets.traitlets.TraitError: The 'timeout' trait of an ExecutePreprocessor instance must be an int, but a value of 'none' <class 'str'> was specified.
Mon Sep  9 16:50:01 UTC 2019
Refreshing 02calculation
[NbConvertApp] Converting notebook 02-calculation.ipynb to notebook
[NbConvertApp] Executing notebook with kernel: python3
[NbConvertApp] ERROR | Error while converting '02-calculation.ipynb'
Traceback (most recent call last):
  File "/home/conniecc1/venv/lib/python3.5/site-packages/nbconvert/nbconvertapp.py", line 393, in export_single_notebook
    output, resources = self.exporter.from_filename(notebook_filename, resources=resources)
  File "/home/conniecc1/venv/lib/python3.5/site-packages/nbconvert/exporters/exporter.py", line 174, in from_filename
    return self.from_file(f, resources=resources, **kw)
  File "/home/conniecc1/venv/lib/python3.5/site-packages/nbconvert/exporters/exporter.py", line 192, in from_file
    return self.from_notebook_node(nbformat.read(file_stream, as_version=4), resources=resources, **kw)
  File "/home/conniecc1/venv/lib/python3.5/site-packages/nbconvert/exporters/notebook.py", line 31, in from_notebook_node
    nb_copy, resources = super(NotebookExporter, self).from_notebook_node(nb, resources, **kw)
  File "/home/conniecc1/venv/lib/python3.5/site-packages/nbconvert/exporters/exporter.py", line 134, in from_notebook_node
    nb_copy, resources = self._preprocess(nb_copy, resources)
  File "/home/conniecc1/venv/lib/python3.5/site-packages/nbconvert/exporters/exporter.py", line 311, in _preprocess
    nbc, resc = preprocessor(nbc, resc)
  File "/home/conniecc1/venv/lib/python3.5/site-packages/nbconvert/preprocessors/base.py", line 47, in __call__
    return self.preprocess(nb, resources)
  File "/home/conniecc1/venv/lib/python3.5/site-packages/nbconvert/preprocessors/execute.py", line 262, in preprocess
    nb, resources = super(ExecutePreprocessor, self).preprocess(nb, resources)
  File "/home/conniecc1/venv/lib/python3.5/site-packages/nbconvert/preprocessors/base.py", line 69, in preprocess
    nb.cells[index], resources = self.preprocess_cell(cell, resources, index)
  File "/home/conniecc1/venv/lib/python3.5/site-packages/nbconvert/preprocessors/execute.py", line 286, in preprocess_cell
    raise CellExecutionError.from_cell_and_msg(cell, out)
nbconvert.preprocessors.execute.CellExecutionError: An error occurred while executing the following cell:
------------------
total_new = get_new_pages().rename(columns={"new_pages": "net_new_content_pages"})
api_results.append(total_new)
------------------

[0;31m---------------------------------------------------------------------------[0m
[0;31mTimeoutError[0m                              Traceback (most recent call last)
[0;32m~/venv/lib/python3.5/site-packages/urllib3/connection.py[0m in [0;36m_new_conn[0;34m(self)[0m
[1;32m    170[0m             conn = connection.create_connection(
[0;32m--> 171[0;31m                 (self._dns_host, self.port), self.timeout, **extra_kw)
[0m[1;32m    172[0m [0;34m[0m[0m

[0;32m~/venv/lib/python3.5/site-packages/urllib3/util/connection.py[0m in [0;36mcreate_connection[0;34m(address, timeout, source_address, socket_options)[0m
[1;32m     78[0m     [0;32mif[0m [0merr[0m [0;32mis[0m [0;32mnot[0m [0;32mNone[0m[0;34m:[0m[0;34m[0m[0m
[0;32m---> 79[0;31m         [0;32mraise[0m [0merr[0m[0;34m[0m[0m
[0m[1;32m     80[0m [0;34m[0m[0m

[0;32m~/venv/lib/python3.5/site-packages/urllib3/util/connection.py[0m in [0;36mcreate_connection[0;34m(address, timeout, source_address, socket_options)[0m
[1;32m     68[0m                 [0msock[0m[0;34m.[0m[0mbind[0m[0;34m([0m[0msource_address[0m[0;34m)[0m[0;34m[0m[0m
[0;32m---> 69[0;31m             [0msock[0m[0;34m.[0m[0mconnect[0m[0;34m([0m[0msa[0m[0;34m)[0m[0;34m[0m[0m
[0m[1;32m     70[0m             [0;32mreturn[0m [0msock[0m[0;34m[0m[0m

[0;31mTimeoutError[0m: [Errno 110] Connection timed out

During handling of the above exception, another exception occurred:

[0;31mNewConnectionError[0m                        Traceback (most recent call last)
[0;32m~/venv/lib/python3.5/site-packages/urllib3/connectionpool.py[0m in [0;36murlopen[0;34m(self, method, url, body, headers, retries, redirect, assert_same_host, timeout, pool_timeout, release_conn, chunked, body_pos, **response_kw)[0m
[1;32m    599[0m                                                   [0mbody[0m[0;34m=[0m[0mbody[0m[0;34m,[0m [0mheaders[0m[0;34m=[0m[0mheaders[0m[0;34m,[0m[0;34m[0m[0m
[0;32m--> 600[0;31m                                                   chunked=chunked)
[0m[1;32m    601[0m [0;34m[0m[0m

[0;32m~/venv/lib/python3.5/site-packages/urllib3/connectionpool.py[0m in [0;36m_make_request[0;34m(self, conn, method, url, timeout, chunked, **httplib_request_kw)[0m
[1;32m    353[0m         [0;32melse[0m[0;34m:[0m[0;34m[0m[0m
[0;32m--> 354[0;31m             [0mconn[0m[0;34m.[0m[0mrequest[0m[0;34m([0m[0mmethod[0m[0;34m,[0m [0murl[0m[0;34m,[0m [0;34m**[0m[0mhttplib_request_kw[0m[0;34m)[0m[0;34m[0m[0m
[0m[1;32m    355[0m [0;34m[0m[0m

[0;32m/usr/lib/python3.5/http/client.py[0m in [0;36mrequest[0;34m(self, method, url, body, headers)[0m
[1;32m   1106[0m         [0;34m"""Send a complete request to the server."""[0m[0;34m[0m[0m
[0;32m-> 1107[0;31m         [0mself[0m[0;34m.[0m[0m_send_request[0m[0;34m([0m[0mmethod[0m[0;34m,[0m [0murl[0m[0;34m,[0m [0mbody[0m[0;34m,[0m [0mheaders[0m[0;34m)[0m[0;34m[0m[0m
[0m[1;32m   1108[0m [0;34m[0m[0m

[0;32m/usr/lib/python3.5/http/client.py[0m in [0;36m_send_request[0;34m(self, method, url, body, headers)[0m
[1;32m   1151[0m             [0mbody[0m [0;34m=[0m [0m_encode[0m[0;34m([0m[0mbody[0m[0;34m,[0m [0;34m'body'[0m[0;34m)[0m[0;34m[0m[0m
[0;32m-> 1152[0;31m         [0mself[0m[0;34m.[0m[0mendheaders[0m[0;34m([0m[0mbody[0m[0;34m)[0m[0;34m[0m[0m
[0m[1;32m   1153[0m [0;34m[0m[0m

[0;32m/usr/lib/python3.5/http/client.py[0m in [0;36mendheaders[0;34m(self, message_body)[0m
[1;32m   1102[0m             [0;32mraise[0m [0mCannotSendHeader[0m[0;34m([0m[0;34m)[0m[0;34m[0m[0m
[0;32m-> 1103[0;31m         [0mself[0m[0;34m.[0m[0m_send_output[0m[0;34m([0m[0mmessage_body[0m[0;34m)[0m[0;34m[0m[0m
[0m[1;32m   1104[0m [0;34m[0m[0m

[0;32m/usr/lib/python3.5/http/client.py[0m in [0;36m_send_output[0;34m(self, message_body)[0m
[1;32m    933[0m [0;34m[0m[0m
[0;32m--> 934[0;31m         [0mself[0m[0;34m.[0m[0msend[0m[0;34m([0m[0mmsg[0m[0;34m)[0m[0;34m[0m[0m
[0m[1;32m    935[0m         [0;32mif[0m [0mmessage_body[0m [0;32mis[0m [0;32mnot[0m [0;32mNone[0m[0;34m:[0m[0;34m[0m[0m

[0;32m/usr/lib/python3.5/http/client.py[0m in [0;36msend[0;34m(self, data)[0m
[1;32m    876[0m             [0;32mif[0m [0mself[0m[0;34m.[0m[0mauto_open[0m[0;34m:[0m[0;34m[0m[0m
[0;32m--> 877[0;31m                 [0mself[0m[0;34m.[0m[0mconnect[0m[0;34m([0m[0;34m)[0m[0;34m[0m[0m
[0m[1;32m    878[0m             [0;32melse[0m[0;34m:[0m[0;34m[0m[0m

[0;32m~/venv/lib/python3.5/site-packages/urllib3/connection.py[0m in [0;36mconnect[0;34m(self)[0m
[1;32m    195[0m     [0;32mdef[0m [0mconnect[0m[0;34m([0m[0mself[0m[0;34m)[0m[0;34m:[0m[0;34m[0m[0m
[0;32m--> 196[0;31m         [0mconn[0m [0;34m=[0m [0mself[0m[0;34m.[0m[0m_new_conn[0m[0;34m([0m[0;34m)[0m[0;34m[0m[0m
[0m[1;32m    197[0m         [0mself[0m[0;34m.[0m[0m_prepare_conn[0m[0;34m([0m[0mconn[0m[0;34m)[0m[0;34m[0m[0m

[0;32m~/venv/lib/python3.5/site-packages/urllib3/connection.py[0m in [0;36m_new_conn[0;34m(self)[0m
[1;32m    179[0m             raise NewConnectionError(
[0;32m--> 180[0;31m                 self, "Failed to establish a new connection: %s" % e)
[0m[1;32m    181[0m [0;34m[0m[0m

[0;31mNewConnectionError[0m: <urllib3.connection.HTTPConnection object at 0x7f7a92166a58>: Failed to establish a new connection: [Errno 110] Connection timed out

During handling of the above exception, another exception occurred:

[0;31mMaxRetryError[0m                             Traceback (most recent call last)
[0;32m~/venv/lib/python3.5/site-packages/requests/adapters.py[0m in [0;36msend[0;34m(self, request, stream, timeout, verify, cert, proxies)[0m
[1;32m    444[0m                     [0mretries[0m[0;34m=[0m[0mself[0m[0;34m.[0m[0mmax_retries[0m[0;34m,[0m[0;34m[0m[0m
[0;32m--> 445[0;31m                     [0mtimeout[0m[0;34m=[0m[0mtimeout[0m[0;34m[0m[0m
[0m[1;32m    446[0m                 )

[0;32m~/venv/lib/python3.5/site-packages/urllib3/connectionpool.py[0m in [0;36murlopen[0;34m(self, method, url, body, headers, retries, redirect, assert_same_host, timeout, pool_timeout, release_conn, chunked, body_pos, **response_kw)[0m
[1;32m    637[0m             retries = retries.increment(method, url, error=e, _pool=self,
[0;32m--> 638[0;31m                                         _stacktrace=sys.exc_info()[2])
[0m[1;32m    639[0m             [0mretries[0m[0;34m.[0m[0msleep[0m[0;34m([0m[0;34m)[0m[0;34m[0m[0m

[0;32m~/venv/lib/python3.5/site-packages/urllib3/util/retry.py[0m in [0;36mincrement[0;34m(self, method, url, response, error, _pool, _stacktrace)[0m
[1;32m    397[0m         [0;32mif[0m [0mnew_retry[0m[0;34m.[0m[0mis_exhausted[0m[0;34m([0m[0;34m)[0m[0;34m:[0m[0;34m[0m[0m
[0;32m--> 398[0;31m             [0;32mraise[0m [0mMaxRetryError[0m[0;34m([0m[0m_pool[0m[0;34m,[0m [0murl[0m[0;34m,[0m [0merror[0m [0;32mor[0m [0mResponseError[0m[0;34m([0m[0mcause[0m[0;34m)[0m[0;34m)[0m[0;34m[0m[0m
[0m[1;32m    399[0m [0;34m[0m[0m

[0;31mMaxRetryError[0m: HTTPConnectionPool(host='aqs1004.eqiad.wmnet', port=7232): Max retries exceeded with url: /analytics.wikimedia.org/v1/edited-pages/new/all-projects/all-editor-types/content/monthly/20190701/20190801 (Caused by NewConnectionError('<urllib3.connection.HTTPConnection object at 0x7f7a92166a58>: Failed to establish a new connection: [Errno 110] Connection timed out',))

During handling of the above exception, another exception occurred:

[0;31mConnectionError[0m                           Traceback (most recent call last)
[0;32m<ipython-input-6-e7ab8219e6d0>[0m in [0;36m<module>[0;34m()[0m
[0;32m----> 1[0;31m [0mtotal_new[0m [0;34m=[0m [0mget_new_pages[0m[0;34m([0m[0;34m)[0m[0;34m.[0m[0mrename[0m[0;34m([0m[0mcolumns[0m[0;34m=[0m[0;34m{[0m[0;34m"new_pages"[0m[0;34m:[0m [0;34m"net_new_content_pages"[0m[0;34m}[0m[0;34m)[0m[0;34m[0m[0m
[0m[1;32m      2[0m [0mapi_results[0m[0;34m.[0m[0mappend[0m[0;34m([0m[0mtotal_new[0m[0;34m)[0m[0;34m[0m[0m

[0;32m<ipython-input-5-bb040ed954cf>[0m in [0;36mget_new_pages[0;34m(project, page_type, start, end)[0m
[1;32m     25[0m     )
[1;32m     26[0m [0;34m[0m[0m
[0;32m---> 27[0;31m     [0mr[0m [0;34m=[0m [0mrequests[0m[0;34m.[0m[0mget[0m[0;34m([0m[0murl[0m[0;34m,[0m [0mheaders[0m[0;34m=[0m[0mheaders[0m[0;34m)[0m[0;34m[0m[0m
[0m[1;32m     28[0m     [0mdata[0m [0;34m=[0m [0mr[0m[0;34m.[0m[0mjson[0m[0;34m([0m[0;34m)[0m[0;34m[[0m[0;34m"items"[0m[0;34m][0m[0;34m[[0m[0;36m0[0m[0;34m][0m[0;34m[[0m[0;34m"results"[0m[0;34m][0m[0;34m[0m[0m
[1;32m     29[0m     [0mframe[0m [0;34m=[0m [0mpd[0m[0;34m.[0m[0mDataFrame[0m[0;34m([0m[0mdata[0m[0;34m)[0m[0;34m[0m[0m

[0;32m~/venv/lib/python3.5/site-packages/requests/api.py[0m in [0;36mget[0;34m(url, params, **kwargs)[0m
[1;32m     70[0m [0;34m[0m[0m
[1;32m     71[0m     [0mkwargs[0m[0;34m.[0m[0msetdefault[0m[0;34m([0m[0;34m'allow_redirects'[0m[0;34m,[0m [0;32mTrue[0m[0;34m)[0m[0;34m[0m[0m
[0;32m---> 72[0;31m     [0;32mreturn[0m [0mrequest[0m[0;34m([0m[0;34m'get'[0m[0;34m,[0m [0murl[0m[0;34m,[0m [0mparams[0m[0;34m=[0m[0mparams[0m[0;34m,[0m [0;34m**[0m[0mkwargs[0m[0;34m)[0m[0;34m[0m[0m
[0m[1;32m     73[0m [0;34m[0m[0m
[1;32m     74[0m [0;34m[0m[0m

[0;32m~/venv/lib/python3.5/site-packages/requests/api.py[0m in [0;36mrequest[0;34m(method, url, **kwargs)[0m
[1;32m     56[0m     [0;31m# cases, and look like a memory leak in others.[0m[0;34m[0m[0;34m[0m[0m
[1;32m     57[0m     [0;32mwith[0m [0msessions[0m[0;34m.[0m[0mSession[0m[0;34m([0m[0;34m)[0m [0;32mas[0m [0msession[0m[0;34m:[0m[0;34m[0m[0m
[0;32m---> 58[0;31m         [0;32mreturn[0m [0msession[0m[0;34m.[0m[0mrequest[0m[0;34m([0m[0mmethod[0m[0;34m=[0m[0mmethod[0m[0;34m,[0m [0murl[0m[0;34m=[0m[0murl[0m[0;34m,[0m [0;34m**[0m[0mkwargs[0m[0;34m)[0m[0;34m[0m[0m
[0m[1;32m     59[0m [0;34m[0m[0m
[1;32m     60[0m [0;34m[0m[0m

[0;32m~/venv/lib/python3.5/site-packages/requests/sessions.py[0m in [0;36mrequest[0;34m(self, method, url, params, data, headers, cookies, files, auth, timeout, allow_redirects, proxies, hooks, stream, verify, cert, json)[0m
[1;32m    510[0m         }
[1;32m    511[0m         [0msend_kwargs[0m[0;34m.[0m[0mupdate[0m[0;34m([0m[0msettings[0m[0;34m)[0m[0;34m[0m[0m
[0;32m--> 512[0;31m         [0mresp[0m [0;34m=[0m [0mself[0m[0;34m.[0m[0msend[0m[0;34m([0m[0mprep[0m[0;34m,[0m [0;34m**[0m[0msend_kwargs[0m[0;34m)[0m[0;34m[0m[0m
[0m[1;32m    513[0m [0;34m[0m[0m
[1;32m    514[0m         [0;32mreturn[0m [0mresp[0m[0;34m[0m[0m

[0;32m~/venv/lib/python3.5/site-packages/requests/sessions.py[0m in [0;36msend[0;34m(self, request, **kwargs)[0m
[1;32m    620[0m [0;34m[0m[0m
[1;32m    621[0m         [0;31m# Send the request[0m[0;34m[0m[0;34m[0m[0m
[0;32m--> 622[0;31m         [0mr[0m [0;34m=[0m [0madapter[0m[0;34m.[0m[0msend[0m[0;34m([0m[0mrequest[0m[0;34m,[0m [0;34m**[0m[0mkwargs[0m[0;34m)[0m[0;34m[0m[0m
[0m[1;32m    623[0m [0;34m[0m[0m
[1;32m    624[0m         [0;31m# Total elapsed time of the request (approximately)[0m[0;34m[0m[0;34m[0m[0m

[0;32m~/venv/lib/python3.5/site-packages/requests/adapters.py[0m in [0;36msend[0;34m(self, request, stream, timeout, verify, cert, proxies)[0m
[1;32m    511[0m                 [0;32mraise[0m [0mSSLError[0m[0;34m([0m[0me[0m[0;34m,[0m [0mrequest[0m[0;34m=[0m[0mrequest[0m[0;34m)[0m[0;34m[0m[0m
[1;32m    512[0m [0;34m[0m[0m
[0;32m--> 513[0;31m             [0;32mraise[0m [0mConnectionError[0m[0;34m([0m[0me[0m[0;34m,[0m [0mrequest[0m[0;34m=[0m[0mrequest[0m[0;34m)[0m[0;34m[0m[0m
[0m[1;32m    514[0m [0;34m[0m[0m
[1;32m    515[0m         [0;32mexcept[0m [0mClosedPoolError[0m [0;32mas[0m [0me[0m[0;34m:[0m[0;34m[0m[0m

[0;31mConnectionError[0m: HTTPConnectionPool(host='aqs1004.eqiad.wmnet', port=7232): Max retries exceeded with url: /analytics.wikimedia.org/v1/edited-pages/new/all-projects/all-editor-types/content/monthly/20190701/20190801 (Caused by NewConnectionError('<urllib3.connection.HTTPConnection object at 0x7f7a92166a58>: Failed to establish a new connection: [Errno 110] Connection timed out',))
ConnectionError: HTTPConnectionPool(host='aqs1004.eqiad.wmnet', port=7232): Max retries exceeded with url: /analytics.wikimedia.org/v1/edited-pages/new/all-projects/all-editor-types/content/monthly/20190701/20190801 (Caused by NewConnectionError('<urllib3.connection.HTTPConnection object at 0x7f7a92166a58>: Failed to establish a new connection: [Errno 110] Connection timed out',))

Mon Sep 16 16:50:01 UTC 2019
Refreshing 02calculation
[NbConvertApp] Converting notebook 02-calculation.ipynb to notebook
[NbConvertApp] Executing notebook with kernel: python3
[NbConvertApp] ERROR | Error while converting '02-calculation.ipynb'
Traceback (most recent call last):
  File "/home/conniecc1/venv/lib/python3.5/site-packages/nbconvert/nbconvertapp.py", line 393, in export_single_notebook
    output, resources = self.exporter.from_filename(notebook_filename, resources=resources)
  File "/home/conniecc1/venv/lib/python3.5/site-packages/nbconvert/exporters/exporter.py", line 174, in from_filename
    return self.from_file(f, resources=resources, **kw)
  File "/home/conniecc1/venv/lib/python3.5/site-packages/nbconvert/exporters/exporter.py", line 192, in from_file
    return self.from_notebook_node(nbformat.read(file_stream, as_version=4), resources=resources, **kw)
  File "/home/conniecc1/venv/lib/python3.5/site-packages/nbconvert/exporters/notebook.py", line 31, in from_notebook_node
    nb_copy, resources = super(NotebookExporter, self).from_notebook_node(nb, resources, **kw)
  File "/home/conniecc1/venv/lib/python3.5/site-packages/nbconvert/exporters/exporter.py", line 134, in from_notebook_node
    nb_copy, resources = self._preprocess(nb_copy, resources)
  File "/home/conniecc1/venv/lib/python3.5/site-packages/nbconvert/exporters/exporter.py", line 311, in _preprocess
    nbc, resc = preprocessor(nbc, resc)
  File "/home/conniecc1/venv/lib/python3.5/site-packages/nbconvert/preprocessors/base.py", line 47, in __call__
    return self.preprocess(nb, resources)
  File "/home/conniecc1/venv/lib/python3.5/site-packages/nbconvert/preprocessors/execute.py", line 262, in preprocess
    nb, resources = super(ExecutePreprocessor, self).preprocess(nb, resources)
  File "/home/conniecc1/venv/lib/python3.5/site-packages/nbconvert/preprocessors/base.py", line 69, in preprocess
    nb.cells[index], resources = self.preprocess_cell(cell, resources, index)
  File "/home/conniecc1/venv/lib/python3.5/site-packages/nbconvert/preprocessors/execute.py", line 286, in preprocess_cell
    raise CellExecutionError.from_cell_and_msg(cell, out)
nbconvert.preprocessors.execute.CellExecutionError: An error occurred while executing the following cell:
------------------
total_new = get_new_pages().rename(columns={"new_pages": "net_new_content_pages"})
api_results.append(total_new)
------------------

[0;31m---------------------------------------------------------------------------[0m
[0;31mTimeoutError[0m                              Traceback (most recent call last)
[0;32m~/venv/lib/python3.5/site-packages/urllib3/connection.py[0m in [0;36m_new_conn[0;34m(self)[0m
[1;32m    170[0m             conn = connection.create_connection(
[0;32m--> 171[0;31m                 (self._dns_host, self.port), self.timeout, **extra_kw)
[0m[1;32m    172[0m [0;34m[0m[0m

[0;32m~/venv/lib/python3.5/site-packages/urllib3/util/connection.py[0m in [0;36mcreate_connection[0;34m(address, timeout, source_address, socket_options)[0m
[1;32m     78[0m     [0;32mif[0m [0merr[0m [0;32mis[0m [0;32mnot[0m [0;32mNone[0m[0;34m:[0m[0;34m[0m[0m
[0;32m---> 79[0;31m         [0;32mraise[0m [0merr[0m[0;34m[0m[0m
[0m[1;32m     80[0m [0;34m[0m[0m

[0;32m~/venv/lib/python3.5/site-packages/urllib3/util/connection.py[0m in [0;36mcreate_connection[0;34m(address, timeout, source_address, socket_options)[0m
[1;32m     68[0m                 [0msock[0m[0;34m.[0m[0mbind[0m[0;34m([0m[0msource_address[0m[0;34m)[0m[0;34m[0m[0m
[0;32m---> 69[0;31m             [0msock[0m[0;34m.[0m[0mconnect[0m[0;34m([0m[0msa[0m[0;34m)[0m[0;34m[0m[0m
[0m[1;32m     70[0m             [0;32mreturn[0m [0msock[0m[0;34m[0m[0m

[0;31mTimeoutError[0m: [Errno 110] Connection timed out

During handling of the above exception, another exception occurred:

[0;31mNewConnectionError[0m                        Traceback (most recent call last)
[0;32m~/venv/lib/python3.5/site-packages/urllib3/connectionpool.py[0m in [0;36murlopen[0;34m(self, method, url, body, headers, retries, redirect, assert_same_host, timeout, pool_timeout, release_conn, chunked, body_pos, **response_kw)[0m
[1;32m    599[0m                                                   [0mbody[0m[0;34m=[0m[0mbody[0m[0;34m,[0m [0mheaders[0m[0;34m=[0m[0mheaders[0m[0;34m,[0m[0;34m[0m[0m
[0;32m--> 600[0;31m                                                   chunked=chunked)
[0m[1;32m    601[0m [0;34m[0m[0m

[0;32m~/venv/lib/python3.5/site-packages/urllib3/connectionpool.py[0m in [0;36m_make_request[0;34m(self, conn, method, url, timeout, chunked, **httplib_request_kw)[0m
[1;32m    353[0m         [0;32melse[0m[0;34m:[0m[0;34m[0m[0m
[0;32m--> 354[0;31m             [0mconn[0m[0;34m.[0m[0mrequest[0m[0;34m([0m[0mmethod[0m[0;34m,[0m [0murl[0m[0;34m,[0m [0;34m**[0m[0mhttplib_request_kw[0m[0;34m)[0m[0;34m[0m[0m
[0m[1;32m    355[0m [0;34m[0m[0m

[0;32m/usr/lib/python3.5/http/client.py[0m in [0;36mrequest[0;34m(self, method, url, body, headers)[0m
[1;32m   1106[0m         [0;34m"""Send a complete request to the server."""[0m[0;34m[0m[0m
[0;32m-> 1107[0;31m         [0mself[0m[0;34m.[0m[0m_send_request[0m[0;34m([0m[0mmethod[0m[0;34m,[0m [0murl[0m[0;34m,[0m [0mbody[0m[0;34m,[0m [0mheaders[0m[0;34m)[0m[0;34m[0m[0m
[0m[1;32m   1108[0m [0;34m[0m[0m

[0;32m/usr/lib/python3.5/http/client.py[0m in [0;36m_send_request[0;34m(self, method, url, body, headers)[0m
[1;32m   1151[0m             [0mbody[0m [0;34m=[0m [0m_encode[0m[0;34m([0m[0mbody[0m[0;34m,[0m [0;34m'body'[0m[0;34m)[0m[0;34m[0m[0m
[0;32m-> 1152[0;31m         [0mself[0m[0;34m.[0m[0mendheaders[0m[0;34m([0m[0mbody[0m[0;34m)[0m[0;34m[0m[0m
[0m[1;32m   1153[0m [0;34m[0m[0m

[0;32m/usr/lib/python3.5/http/client.py[0m in [0;36mendheaders[0;34m(self, message_body)[0m
[1;32m   1102[0m             [0;32mraise[0m [0mCannotSendHeader[0m[0;34m([0m[0;34m)[0m[0;34m[0m[0m
[0;32m-> 1103[0;31m         [0mself[0m[0;34m.[0m[0m_send_output[0m[0;34m([0m[0mmessage_body[0m[0;34m)[0m[0;34m[0m[0m
[0m[1;32m   1104[0m [0;34m[0m[0m

[0;32m/usr/lib/python3.5/http/client.py[0m in [0;36m_send_output[0;34m(self, message_body)[0m
[1;32m    933[0m [0;34m[0m[0m
[0;32m--> 934[0;31m         [0mself[0m[0;34m.[0m[0msend[0m[0;34m([0m[0mmsg[0m[0;34m)[0m[0;34m[0m[0m
[0m[1;32m    935[0m         [0;32mif[0m [0mmessage_body[0m [0;32mis[0m [0;32mnot[0m [0;32mNone[0m[0;34m:[0m[0;34m[0m[0m

[0;32m/usr/lib/python3.5/http/client.py[0m in [0;36msend[0;34m(self, data)[0m
[1;32m    876[0m             [0;32mif[0m [0mself[0m[0;34m.[0m[0mauto_open[0m[0;34m:[0m[0;34m[0m[0m
[0;32m--> 877[0;31m                 [0mself[0m[0;34m.[0m[0mconnect[0m[0;34m([0m[0;34m)[0m[0;34m[0m[0m
[0m[1;32m    878[0m             [0;32melse[0m[0;34m:[0m[0;34m[0m[0m

[0;32m~/venv/lib/python3.5/site-packages/urllib3/connection.py[0m in [0;36mconnect[0;34m(self)[0m
[1;32m    195[0m     [0;32mdef[0m [0mconnect[0m[0;34m([0m[0mself[0m[0;34m)[0m[0;34m:[0m[0;34m[0m[0m
[0;32m--> 196[0;31m         [0mconn[0m [0;34m=[0m [0mself[0m[0;34m.[0m[0m_new_conn[0m[0;34m([0m[0;34m)[0m[0;34m[0m[0m
[0m[1;32m    197[0m         [0mself[0m[0;34m.[0m[0m_prepare_conn[0m[0;34m([0m[0mconn[0m[0;34m)[0m[0;34m[0m[0m

[0;32m~/venv/lib/python3.5/site-packages/urllib3/connection.py[0m in [0;36m_new_conn[0;34m(self)[0m
[1;32m    179[0m             raise NewConnectionError(
[0;32m--> 180[0;31m                 self, "Failed to establish a new connection: %s" % e)
[0m[1;32m    181[0m [0;34m[0m[0m

[0;31mNewConnectionError[0m: <urllib3.connection.HTTPConnection object at 0x7f16e0c55710>: Failed to establish a new connection: [Errno 110] Connection timed out

During handling of the above exception, another exception occurred:

[0;31mMaxRetryError[0m                             Traceback (most recent call last)
[0;32m~/venv/lib/python3.5/site-packages/requests/adapters.py[0m in [0;36msend[0;34m(self, request, stream, timeout, verify, cert, proxies)[0m
[1;32m    444[0m                     [0mretries[0m[0;34m=[0m[0mself[0m[0;34m.[0m[0mmax_retries[0m[0;34m,[0m[0;34m[0m[0m
[0;32m--> 445[0;31m                     [0mtimeout[0m[0;34m=[0m[0mtimeout[0m[0;34m[0m[0m
[0m[1;32m    446[0m                 )

[0;32m~/venv/lib/python3.5/site-packages/urllib3/connectionpool.py[0m in [0;36murlopen[0;34m(self, method, url, body, headers, retries, redirect, assert_same_host, timeout, pool_timeout, release_conn, chunked, body_pos, **response_kw)[0m
[1;32m    637[0m             retries = retries.increment(method, url, error=e, _pool=self,
[0;32m--> 638[0;31m                                         _stacktrace=sys.exc_info()[2])
[0m[1;32m    639[0m             [0mretries[0m[0;34m.[0m[0msleep[0m[0;34m([0m[0;34m)[0m[0;34m[0m[0m

[0;32m~/venv/lib/python3.5/site-packages/urllib3/util/retry.py[0m in [0;36mincrement[0;34m(self, method, url, response, error, _pool, _stacktrace)[0m
[1;32m    397[0m         [0;32mif[0m [0mnew_retry[0m[0;34m.[0m[0mis_exhausted[0m[0;34m([0m[0;34m)[0m[0;34m:[0m[0;34m[0m[0m
[0;32m--> 398[0;31m             [0;32mraise[0m [0mMaxRetryError[0m[0;34m([0m[0m_pool[0m[0;34m,[0m [0murl[0m[0;34m,[0m [0merror[0m [0;32mor[0m [0mResponseError[0m[0;34m([0m[0mcause[0m[0;34m)[0m[0;34m)[0m[0;34m[0m[0m
[0m[1;32m    399[0m [0;34m[0m[0m

[0;31mMaxRetryError[0m: HTTPConnectionPool(host='aqs1004.eqiad.wmnet', port=7232): Max retries exceeded with url: /analytics.wikimedia.org/v1/edited-pages/new/all-projects/all-editor-types/content/monthly/20190801/20190901 (Caused by NewConnectionError('<urllib3.connection.HTTPConnection object at 0x7f16e0c55710>: Failed to establish a new connection: [Errno 110] Connection timed out',))

During handling of the above exception, another exception occurred:

[0;31mConnectionError[0m                           Traceback (most recent call last)
[0;32m<ipython-input-6-e7ab8219e6d0>[0m in [0;36m<module>[0;34m()[0m
[0;32m----> 1[0;31m [0mtotal_new[0m [0;34m=[0m [0mget_new_pages[0m[0;34m([0m[0;34m)[0m[0;34m.[0m[0mrename[0m[0;34m([0m[0mcolumns[0m[0;34m=[0m[0;34m{[0m[0;34m"new_pages"[0m[0;34m:[0m [0;34m"net_new_content_pages"[0m[0;34m}[0m[0;34m)[0m[0;34m[0m[0m
[0m[1;32m      2[0m [0mapi_results[0m[0;34m.[0m[0mappend[0m[0;34m([0m[0mtotal_new[0m[0;34m)[0m[0;34m[0m[0m

[0;32m<ipython-input-5-bb040ed954cf>[0m in [0;36mget_new_pages[0;34m(project, page_type, start, end)[0m
[1;32m     25[0m     )
[1;32m     26[0m [0;34m[0m[0m
[0;32m---> 27[0;31m     [0mr[0m [0;34m=[0m [0mrequests[0m[0;34m.[0m[0mget[0m[0;34m([0m[0murl[0m[0;34m,[0m [0mheaders[0m[0;34m=[0m[0mheaders[0m[0;34m)[0m[0;34m[0m[0m
[0m[1;32m     28[0m     [0mdata[0m [0;34m=[0m [0mr[0m[0;34m.[0m[0mjson[0m[0;34m([0m[0;34m)[0m[0;34m[[0m[0;34m"items"[0m[0;34m][0m[0;34m[[0m[0;36m0[0m[0;34m][0m[0;34m[[0m[0;34m"results"[0m[0;34m][0m[0;34m[0m[0m
[1;32m     29[0m     [0mframe[0m [0;34m=[0m [0mpd[0m[0;34m.[0m[0mDataFrame[0m[0;34m([0m[0mdata[0m[0;34m)[0m[0;34m[0m[0m

[0;32m~/venv/lib/python3.5/site-packages/requests/api.py[0m in [0;36mget[0;34m(url, params, **kwargs)[0m
[1;32m     70[0m [0;34m[0m[0m
[1;32m     71[0m     [0mkwargs[0m[0;34m.[0m[0msetdefault[0m[0;34m([0m[0;34m'allow_redirects'[0m[0;34m,[0m [0;32mTrue[0m[0;34m)[0m[0;34m[0m[0m
[0;32m---> 72[0;31m     [0;32mreturn[0m [0mrequest[0m[0;34m([0m[0;34m'get'[0m[0;34m,[0m [0murl[0m[0;34m,[0m [0mparams[0m[0;34m=[0m[0mparams[0m[0;34m,[0m [0;34m**[0m[0mkwargs[0m[0;34m)[0m[0;34m[0m[0m
[0m[1;32m     73[0m [0;34m[0m[0m
[1;32m     74[0m [0;34m[0m[0m

[0;32m~/venv/lib/python3.5/site-packages/requests/api.py[0m in [0;36mrequest[0;34m(method, url, **kwargs)[0m
[1;32m     56[0m     [0;31m# cases, and look like a memory leak in others.[0m[0;34m[0m[0;34m[0m[0m
[1;32m     57[0m     [0;32mwith[0m [0msessions[0m[0;34m.[0m[0mSession[0m[0;34m([0m[0;34m)[0m [0;32mas[0m [0msession[0m[0;34m:[0m[0;34m[0m[0m
[0;32m---> 58[0;31m         [0;32mreturn[0m [0msession[0m[0;34m.[0m[0mrequest[0m[0;34m([0m[0mmethod[0m[0;34m=[0m[0mmethod[0m[0;34m,[0m [0murl[0m[0;34m=[0m[0murl[0m[0;34m,[0m [0;34m**[0m[0mkwargs[0m[0;34m)[0m[0;34m[0m[0m
[0m[1;32m     59[0m [0;34m[0m[0m
[1;32m     60[0m [0;34m[0m[0m

[0;32m~/venv/lib/python3.5/site-packages/requests/sessions.py[0m in [0;36mrequest[0;34m(self, method, url, params, data, headers, cookies, files, auth, timeout, allow_redirects, proxies, hooks, stream, verify, cert, json)[0m
[1;32m    510[0m         }
[1;32m    511[0m         [0msend_kwargs[0m[0;34m.[0m[0mupdate[0m[0;34m([0m[0msettings[0m[0;34m)[0m[0;34m[0m[0m
[0;32m--> 512[0;31m         [0mresp[0m [0;34m=[0m [0mself[0m[0;34m.[0m[0msend[0m[0;34m([0m[0mprep[0m[0;34m,[0m [0;34m**[0m[0msend_kwargs[0m[0;34m)[0m[0;34m[0m[0m
[0m[1;32m    513[0m [0;34m[0m[0m
[1;32m    514[0m         [0;32mreturn[0m [0mresp[0m[0;34m[0m[0m

[0;32m~/venv/lib/python3.5/site-packages/requests/sessions.py[0m in [0;36msend[0;34m(self, request, **kwargs)[0m
[1;32m    620[0m [0;34m[0m[0m
[1;32m    621[0m         [0;31m# Send the request[0m[0;34m[0m[0;34m[0m[0m
[0;32m--> 622[0;31m         [0mr[0m [0;34m=[0m [0madapter[0m[0;34m.[0m[0msend[0m[0;34m([0m[0mrequest[0m[0;34m,[0m [0;34m**[0m[0mkwargs[0m[0;34m)[0m[0;34m[0m[0m
[0m[1;32m    623[0m [0;34m[0m[0m
[1;32m    624[0m         [0;31m# Total elapsed time of the request (approximately)[0m[0;34m[0m[0;34m[0m[0m

[0;32m~/venv/lib/python3.5/site-packages/requests/adapters.py[0m in [0;36msend[0;34m(self, request, stream, timeout, verify, cert, proxies)[0m
[1;32m    511[0m                 [0;32mraise[0m [0mSSLError[0m[0;34m([0m[0me[0m[0;34m,[0m [0mrequest[0m[0;34m=[0m[0mrequest[0m[0;34m)[0m[0;34m[0m[0m
[1;32m    512[0m [0;34m[0m[0m
[0;32m--> 513[0;31m             [0;32mraise[0m [0mConnectionError[0m[0;34m([0m[0me[0m[0;34m,[0m [0mrequest[0m[0;34m=[0m[0mrequest[0m[0;34m)[0m[0;34m[0m[0m
[0m[1;32m    514[0m [0;34m[0m[0m
[1;32m    515[0m         [0;32mexcept[0m [0mClosedPoolError[0m [0;32mas[0m [0me[0m[0;34m:[0m[0;34m[0m[0m

[0;31mConnectionError[0m: HTTPConnectionPool(host='aqs1004.eqiad.wmnet', port=7232): Max retries exceeded with url: /analytics.wikimedia.org/v1/edited-pages/new/all-projects/all-editor-types/content/monthly/20190801/20190901 (Caused by NewConnectionError('<urllib3.connection.HTTPConnection object at 0x7f16e0c55710>: Failed to establish a new connection: [Errno 110] Connection timed out',))
ConnectionError: HTTPConnectionPool(host='aqs1004.eqiad.wmnet', port=7232): Max retries exceeded with url: /analytics.wikimedia.org/v1/edited-pages/new/all-projects/all-editor-types/content/monthly/20190801/20190901 (Caused by NewConnectionError('<urllib3.connection.HTTPConnection object at 0x7f16e0c55710>: Failed to establish a new connection: [Errno 110] Connection timed out',))

